Traceback (most recent call last):
  File "/gpfsnyu/home/mx648/.conda/envs/mycapstone/lib/python3.8/urllib/request.py", line 1354, in do_open
    h.request(req.get_method(), req.selector, req.data, headers,
  File "/gpfsnyu/home/mx648/.conda/envs/mycapstone/lib/python3.8/http/client.py", line 1256, in request
    self._send_request(method, url, body, headers, encode_chunked)
  File "/gpfsnyu/home/mx648/.conda/envs/mycapstone/lib/python3.8/http/client.py", line 1302, in _send_request
    self.endheaders(body, encode_chunked=encode_chunked)
  File "/gpfsnyu/home/mx648/.conda/envs/mycapstone/lib/python3.8/http/client.py", line 1251, in endheaders
    self._send_output(message_body, encode_chunked=encode_chunked)
  File "/gpfsnyu/home/mx648/.conda/envs/mycapstone/lib/python3.8/http/client.py", line 1011, in _send_output
    self.send(msg)
  File "/gpfsnyu/home/mx648/.conda/envs/mycapstone/lib/python3.8/http/client.py", line 951, in send
    self.connect()
  File "/gpfsnyu/home/mx648/.conda/envs/mycapstone/lib/python3.8/http/client.py", line 1418, in connect
    super().connect()
  File "/gpfsnyu/home/mx648/.conda/envs/mycapstone/lib/python3.8/http/client.py", line 922, in connect
    self.sock = self._create_connection(
  File "/gpfsnyu/home/mx648/.conda/envs/mycapstone/lib/python3.8/socket.py", line 787, in create_connection
    for res in getaddrinfo(host, port, 0, SOCK_STREAM):
  File "/gpfsnyu/home/mx648/.conda/envs/mycapstone/lib/python3.8/socket.py", line 918, in getaddrinfo
    for res in _socket.getaddrinfo(host, port, family, type, proto, flags):
socket.gaierror: [Errno -3] Temporary failure in name resolution

During handling of the above exception, another exception occurred:

Traceback (most recent call last):
  File "dua.py", line 73, in <module>
    teset, teloader = prepare_test_data(args)
  File "/gpfsnyu/scratch/mx648/Capstone/Capstone_Project_Fall_2022/DUA-master/utils/data_loader.py", line 37, in prepare_test_data
    teset = torchvision.datasets.CIFAR10(root=args.dataroot,
  File "/gpfsnyu/home/mx648/.conda/envs/mycapstone/lib/python3.8/site-packages/torchvision/datasets/cifar.py", line 65, in __init__
    self.download()
  File "/gpfsnyu/home/mx648/.conda/envs/mycapstone/lib/python3.8/site-packages/torchvision/datasets/cifar.py", line 141, in download
    download_and_extract_archive(self.url, self.root, filename=self.filename, md5=self.tgz_md5)
  File "/gpfsnyu/home/mx648/.conda/envs/mycapstone/lib/python3.8/site-packages/torchvision/datasets/utils.py", line 446, in download_and_extract_archive
    download_url(url, download_root, filename, md5)
  File "/gpfsnyu/home/mx648/.conda/envs/mycapstone/lib/python3.8/site-packages/torchvision/datasets/utils.py", line 146, in download_url
    url = _get_redirect_url(url, max_hops=max_redirect_hops)
  File "/gpfsnyu/home/mx648/.conda/envs/mycapstone/lib/python3.8/site-packages/torchvision/datasets/utils.py", line 94, in _get_redirect_url
    with urllib.request.urlopen(urllib.request.Request(url, headers=headers)) as response:
  File "/gpfsnyu/home/mx648/.conda/envs/mycapstone/lib/python3.8/urllib/request.py", line 222, in urlopen
    return opener.open(url, data, timeout)
  File "/gpfsnyu/home/mx648/.conda/envs/mycapstone/lib/python3.8/urllib/request.py", line 525, in open
    response = self._open(req, data)
  File "/gpfsnyu/home/mx648/.conda/envs/mycapstone/lib/python3.8/urllib/request.py", line 542, in _open
    result = self._call_chain(self.handle_open, protocol, protocol +
  File "/gpfsnyu/home/mx648/.conda/envs/mycapstone/lib/python3.8/urllib/request.py", line 502, in _call_chain
    result = func(*args)
  File "/gpfsnyu/home/mx648/.conda/envs/mycapstone/lib/python3.8/urllib/request.py", line 1397, in https_open
    return self.do_open(http.client.HTTPSConnection, req,
  File "/gpfsnyu/home/mx648/.conda/envs/mycapstone/lib/python3.8/urllib/request.py", line 1357, in do_open
    raise URLError(err)
urllib.error.URLError: <urlopen error [Errno -3] Temporary failure in name resolution>
